Workbook

Sheet 单方案反推计算器
A1: 感应线圈匹配反推计算器（单方案：短线圈/Nagaoka分支）
A2: 说明：本工作簿按当前截图参数建立。空芯电感采用分支：若 l/Dm≥0.4，则用 Wheeler；若 l/Dm<0.4，则用 Nagaoka 形式 L=Kn·μ0·N²·A/l。当前案例属于短线圈，因此走 Nagaoka 分支。
A4: 基础输入 | F4: 控制/校准参数 | I4: 计算结果
A5: 电源电压 U_LL | B5: 380 | C5: V | F5: 铜管径向宽度 w_rad | G5: 30 | H5: mm | I5: 填充系数 k_f | J5: =B10*B11/B8 -> 0.69538927
A6: 额定功率 P | B6: 100 | C6: kW | F6: 整流系数 k_rect | G6: 1.35 | H6: - | I6: 铜管肌肤深度 δ_cu | J6: =SQRT(2*(B12*0.00000001)/(2*PI()*(B7*1000)*(4*PI()*0.0000001)))*1000 -> 0.71176254 | K6: mm | L6: =J6/10 -> 0.071176254 | M6: cm
A7: 工作频率 f | B7: 10 | C7: kHz | F7: Nagaoka系数 K | G7: 0.96 | H7: - | I7: 炉料肌肤深度 δ_w | J7: =SQRT(2*(B16*0.00000001)/(2*PI()*(B7*1000)*(4*PI()*0.0000001)*B15))*1000 -> 8.7172752 | K7: mm | L7: =J7/10 -> 0.87172752 | M7: cm
A8: 线圈高度 L1 | B8: 1323 | C8: mm | F8: 经验等效电阻 Req | G8: =F54 -> 0.034173936 | H8: Ω | I8: 估算线圈外径 D_out | J8: =B9+2*G5 -> 271.12737 | K8: mm
A9: 线圈内径 D1 | B9: =B14+B40*2+B30*2 -> 211.12737 | C9: mm | D9: 需根据保温厚度+保温层与线圈间隙 | F9: 目标品质因数 Q | G9: 20.1035 | H9: - | I9: 平均直径 D_m | J9: =(B9+J8)/2 -> 241.12737 | K9: mm
A10: 线圈匝数 N | B10: 23 | C10: turn | F10: 线圈交流电阻 R_cu,ac | G10: =C49 -> 0.010716602 | H10: Ω | I10: 径长比 l/Dm | J10: =B9/B8 -> 0.15958229 | K10: -
A11: 铜管高度 h_cu | B11: 40 | C11: mm | F11: 冷却安全系数 k_cool | G11: 1.6126 | H11: - | I11: Wheeler空芯电感 Lw | J11: =(((B9/25.4)^2)*(B10^2))/(18*(B9/25.4)+40*(B8/25.4)) -> 16.367131 | K11: μH | L11: =(((B9/25.4)^2)*(B10^2))/(18*(B9/25.4)+40*(B8/25.4)) -> 16.367131
A12: 铜电阻率 ρ_cu | B12: 2 | C12: ×10^-6 Ω·cm | F12: 水比热 c_p | G12: 4180 | H12: J/kg·K | I12: 理想螺线管电感 Lideal | J12: =(4*PI()*0.0000001*(B10^2)*PI()*((B9/2)/1000)^2/(B8/1000))*G7*1000000 -> 16.887131 | K12: μH
A13: 炉料高度 L2 | B13: 1323 | C13: mm | F13: 水密度 ρ_water | G13: 1 | H13: kg/L | I13: 线圈空芯电感 L0 | J13: =IF(J10>=0.4,J11,G7*J12) -> 16.211646 | K13: μH
A14: 炉料直径 D2 | B14: 120 | C14: mm | F14: Nagaoka系数 K | G14: 0.96 | I14: 感应线圈电流 I | J14: =SQRT((B6*1000)/G8) -> 1710.6159 | K14: A
A15: 炉料相对磁导率 μr,w | B15: 1 | C15: - | F15: 工件长径比D /lm | G15: =B14/B13 -> 0.090702948 | I15: 等效电阻 Req | J15: =G8 -> 0.034173936 | K15: Ω
A16: 炉料电阻率 ρ_w | B16: 300 | C16: ×10^-6 Ω·cm | F16: 并联数 | G16: 1 | I16: 等效电感 Leq | J16: =(G9*J15)/(2*PI()*(B7*1000))*1000000 -> 10.934195 | K16: μH | L16: 此数还需研究，出入较大 | O16: 建议结合有限元仿真（ANSYS Maxwell、COMSOL）进行验证。
A17: 进水温度 T_in | B17: 35 | C17: °C | F17: 品质因数 Q | G17: =2*PI()*B7*1000*J16*0.000001/J15 -> 20.1035 | I17: 感应线圈电压 U_L | J17: =J14*(2*PI()*(B7*1000)*(J16/1000000)) -> 1175.22 | K17: V
A18: 出水温度 T_out | B18: 55 | C18: °C | D18: =B18+273.15 -> 328.15 | E18: K | F18: 外部串联谐振电容C | I18: 有功电压分量 U_R | J18: =J14*J15 -> 58.458477 | K18: V
A19: 炉料匝数 | B19: 1 | I19: 变压器匝数比 n | J19: =(G6*B5)/J18 -> 8.7754595 | K19: -
A20: 铜电阻率 ρ_cu | B20: 1.72 | C20: ×10^-6 Ω·cm | F20: 20℃下的电阻率 | I20: 线圈损耗 P_cu | J20: =(J14^2*G10)/1000 -> 31.358994 | K20: kW | L20: 24.64 | M20: =SQRT(800/C49/B8/1000) -> 0.23753987
A21: 炉料厚度 | B21: 9 | C21: mm
A23: 冷却系统计算
A24: 线圈宽度 | B24: 30 | C24: mm | I24: 冷却水流量 Q_water | J24: =(G11*(J20*1000)/(G12*(B18-B17)))*60/G13 -> 36.293909 | K24: L/min
A25: 线圈厚度 | B25: 4 | C25: mm | I25: 谐振电容 | K25: =B6*0.07 -> 7
A26: 线圈内腔截面积 | B26: =(B11-2*B25)*(B24-2*B25)/1000000 -> 0.000704 | C26: m2 | I26: 冷却水所需最小流量 | J26: =((J20*1000+G40)/(G12*(B18-B17)))*60/G13 -> 29.663212 | K26: L/min | L26: =J26*L28 -> 72
A27: 推荐流速低值 | B27: 1 | C27: m/s | I27: 冷却水所需流速 | J27: =(J20*1000+G40)/(G12*(B18-B17)) -> 0.49438687 | K27: m/s
A28: 推荐流速高值 | B28: 1.5 | C28: m/s | I28: 冷却安全系数 k_cool | J28: =IF(J27<B27,B27/J27,J27) -> 2.0227074 | L28: =J28*1.2 -> 2.4272489 | N28: 长冈系数（由2R/I决定，对照表如下）
A29: 单根管反应所需热负荷 | B29: 1020 | C29: KW | I29: 建议冷却水流量 | J29: =IF(J27<B27,B27*B26*60*1000,J26) -> 42.24 | K29: L/min | L29: =J28*J26 -> 60
A30: 线圈与炉料间隙 | B30: 10 | C30: cm | I30: 建议冷却水实际出水温度 | J30: =(J20*60*1000+G40)/(G12*G13*J29)+B17 -> 45.712942 | K30: °C | L30: 45
A31: 衰减系数 | B31: =2/(B9-B14) -> 0.021947303
A32: 折算系数k | B32: =1/((1+B31*B30)^2) -> 0.67244319
A34: 保温厚度计算
A35: 单程管子总长L | B35: 55.2 | C35: m
A36: 允许的热损失功率Qloss | B36: =B29*1000*0.1 -> 102000 | C36: W | D36: 取加热有效功率的百分比10-30% | F36: 辐射换热,单位面积的热流密度 | G36: =B43*B44*0.00000001*(D39^4-D18^4) -> 32.797245 | H36: W/m2
A37: 保温材料的导热系数λ | B37: =0.028+0.00018*(B38+B39)/2 -> 0.1342 | C37: W/(m.K) | D37: 硅酸铝陶瓷纤维 | F37: 对流传热,单位面积的热流密度q conv ​ | G37: =G43*(B39-L30) -> 358.86332 | H37: W/m2 | I37: 更精确地，可通过计算瑞利数 (Ra) 和努塞尔数 (Nu) 得到 hconv​，但工程上常用经验值进行估算
A38: 工件外表面温度Tinner | B38: 1100 | C38: °C | F38: 单位面积的总热流密度 | G38: =G36+G37 -> 391.66057 | H38: W/m2
A39: 保温层外壁温度Touter | B39: 80 | C39: °C，为保护线圈，不超过100℃ | D39: =B39+273.15 -> 353.15 | E39: K | F39: 线圈的受热面积 Acoil | G39: =PI()*B9/1000*B35*J5 -> 25.46018 | H39: m2
A40: 保温层厚度(D2-D1)/2 | B40: =((EXP(2*PI()*B37*B35*(B38-B39)/B36)*B14/1000)-B14/1000)*1000/2 -> 35.563684 | C40: mm | F40: 总热流密度 | G40: =G38*G39 -> 9971.7486 | H40: W
A41: 保温材料表面发射率 | B41: 0.85 | C41: 陶瓷纤维约0.8~0.9 | F41: 瑞利数Ra | G41: =9.81*(1/D39)*(D39-D18)*(B45/1000)^3/(1.8*0.00001*2.6*0.00001) -> 1483.8977
A42: 铜线圈表面发射率 | B42: 0.15 | C42: 未氧化铜约 0.1~0.2，氧化后可达 0.6 ~0.8 | F42: 努塞尔数（竖直圆筒，层流）Nu | G42: =0.59*G41^(1/4) -> 3.6618707
A43: 有效发射率 | B43: =1/(1/B41+1/B42-1) -> 0.14613181 | F43: 对流传热系数h conv | G43: =G42*B46/(B45/1000) -> 10.253238 | H43: W/(m2⋅K)
...

Sheet 逐步过程
A1: 逐步过程与说明
A2: 步骤 | B2: 项目 | C2: 结果 | D2: 公式/说明
A3: 1 | B3: 填充系数 | C3: =单方案反推计算器!J5 -> 0.69538927 | D3: k_f=N·h_cu/L1
A4: 2 | B4: 铜管肌肤深度 | C4: =单方案反推计算器!J6 -> 0.71176254 | D4: δ=√(2ρ/ωμ)
A5: 3 | B5: 炉料肌肤深度 | C5: =单方案反推计算器!J7 -> 8.7172752 | D5: δ=√(2ρ/ωμ0μr)
A6: 4 | B6: 平均直径/长径比 | C6: =单方案反推计算器!J10 -> 0.15958229 | D6: D_out=D1+2·w_rad；D_m=(D1+D_out)/2
A7: 5 | B7: Wheeler空芯电感 | C7: =单方案反推计算器!J11 -> 16.367131 | D7: 若 l/Dm≥0.4，可参考 Wheeler 原式（英寸制）
A8: 6 | B8: 理想螺线管电感 | C8: =单方案反推计算器!J12 -> 16.887131 | D8: Lideal=μ0·N²·A/l
A9: 7 | B9: 空芯电感分支结果 | C9: =单方案反推计算器!J13 -> 16.211646 | D9: IF(l/Dm≥0.4, Wheeler, Kn·Lideal)；当前案例因 l/Dm<0.4 走 Nagaoka 分支
A10: 8 | B10: 等效电阻/电流 | C10: =单方案反推计算器!J14 -> 1710.6159 | D10: Req 为校准输入；I=√(P/Req)
A11: 9 | B11: 等效电感 | C11: =单方案反推计算器!J16 -> 10.934195 | D11: Leq=Q·Req/(2πf)
A12: 10 | B12: 线圈电压/匝比 | C12: =单方案反推计算器!J19 -> 8.7754595 | D12: U_L=IωLeq；n≈1.35U_LL/(IReq)
A13: 11 | B13: 线圈损耗/水流 | C13: =单方案反推计算器!J24 -> 36.293909 | D13: Pcu=I²Rcu,ac；Qwater=k_cool·Pcu/(ρcpΔT)

Sheet 说明
A1: 说明与局限
A3: 1 | B3: 本表按当前单张截图建立，目的是复现该页结果，不声称已完全还原原软件所有内部专有算法。
A4: 2 | B4: 已较强确认的关系：填充系数、铜/炉料肌肤深度、P=I²Req、Q=ωL/Req、线圈电压、变压器匝数比。
A5: 3 | B5: 空芯电感采用分支逻辑：l/Dm≥0.4 走 Wheeler；l/Dm<0.4 走 Nagaoka 形式。当前案例 l/Dm 明显小于 0.4。
A6: 4 | B6: 几何与材料如何正向推出 Req 仍未完全锁定，因此 Req 仍作为校准输入。
A7: 5 | B7: 线圈损耗采用固定交流铜阻 R_cu,ac；冷却水流量采用热平衡+安全系数近似。
